Traceback (most recent call last):
  File "/Users/avinasharavind/Documents/Weather_Projects/NWS_Forecast_Page/python/data.py", line 23, in <module>
    time.sleep(1)
KeyboardInterrupt
Traceback (most recent call last):
  File "/opt/anaconda3/lib/python3.11/site-packages/urllib3/connection.py", line 203, in _new_conn
    sock = connection.create_connection(
           ^^^^^^^^^^^^^^^^^^^^^^^^^^^^^
  File "/opt/anaconda3/lib/python3.11/site-packages/urllib3/util/connection.py", line 60, in create_connection
    for res in socket.getaddrinfo(host, port, family, socket.SOCK_STREAM):
               ^^^^^^^^^^^^^^^^^^^^^^^^^^^^^^^^^^^^^^^^^^^^^^^^^^^^^^^^^^
  File "/opt/anaconda3/lib/python3.11/socket.py", line 962, in getaddrinfo
    for res in _socket.getaddrinfo(host, port, family, type, proto, flags):
               ^^^^^^^^^^^^^^^^^^^^^^^^^^^^^^^^^^^^^^^^^^^^^^^^^^^^^^^^^^^
socket.gaierror: [Errno 8] nodename nor servname provided, or not known

The above exception was the direct cause of the following exception:

Traceback (most recent call last):
  File "/opt/anaconda3/lib/python3.11/site-packages/urllib3/connectionpool.py", line 791, in urlopen
    response = self._make_request(
               ^^^^^^^^^^^^^^^^^^^
  File "/opt/anaconda3/lib/python3.11/site-packages/urllib3/connectionpool.py", line 492, in _make_request
    raise new_e
  File "/opt/anaconda3/lib/python3.11/site-packages/urllib3/connectionpool.py", line 468, in _make_request
    self._validate_conn(conn)
  File "/opt/anaconda3/lib/python3.11/site-packages/urllib3/connectionpool.py", line 1097, in _validate_conn
    conn.connect()
  File "/opt/anaconda3/lib/python3.11/site-packages/urllib3/connection.py", line 611, in connect
    self.sock = sock = self._new_conn()
                       ^^^^^^^^^^^^^^^^
  File "/opt/anaconda3/lib/python3.11/site-packages/urllib3/connection.py", line 210, in _new_conn
    raise NameResolutionError(self.host, self, e) from e
urllib3.exceptions.NameResolutionError: <urllib3.connection.HTTPSConnection object at 0x127cc3410>: Failed to resolve 'api.weather.gov' ([Errno 8] nodename nor servname provided, or not known)

The above exception was the direct cause of the following exception:

Traceback (most recent call last):
  File "/opt/anaconda3/lib/python3.11/site-packages/requests/adapters.py", line 486, in send
    resp = conn.urlopen(
           ^^^^^^^^^^^^^
  File "/opt/anaconda3/lib/python3.11/site-packages/urllib3/connectionpool.py", line 845, in urlopen
    retries = retries.increment(
              ^^^^^^^^^^^^^^^^^^
  File "/opt/anaconda3/lib/python3.11/site-packages/urllib3/util/retry.py", line 515, in increment
    raise MaxRetryError(_pool, url, reason) from reason  # type: ignore[arg-type]
    ^^^^^^^^^^^^^^^^^^^^^^^^^^^^^^^^^^^^^^^^^^^^^^^^^^^
urllib3.exceptions.MaxRetryError: HTTPSConnectionPool(host='api.weather.gov', port=443): Max retries exceeded with url: /points/42.44,-76.495 (Caused by NameResolutionError("<urllib3.connection.HTTPSConnection object at 0x127cc3410>: Failed to resolve 'api.weather.gov' ([Errno 8] nodename nor servname provided, or not known)"))

During handling of the above exception, another exception occurred:

Traceback (most recent call last):
  File "/Users/avinasharavind/Documents/Weather_Projects/NWS_Forecast_Page/python/data.py", line 22, in <module>
    schedule.run_pending()
  File "/opt/anaconda3/lib/python3.11/site-packages/schedule/__init__.py", line 854, in run_pending
    default_scheduler.run_pending()
  File "/opt/anaconda3/lib/python3.11/site-packages/schedule/__init__.py", line 101, in run_pending
    self._run_job(job)
  File "/opt/anaconda3/lib/python3.11/site-packages/schedule/__init__.py", line 173, in _run_job
    ret = job.run()
          ^^^^^^^^^
  File "/opt/anaconda3/lib/python3.11/site-packages/schedule/__init__.py", line 691, in run
    ret = self.job_func()
          ^^^^^^^^^^^^^^^
  File "/Users/avinasharavind/Documents/Weather_Projects/NWS_Forecast_Page/python/data.py", line 16, in job
    hourly_data("Ithaca, NY")
  File "/Users/avinasharavind/Documents/Weather_Projects/NWS_Forecast_Page/python/data.py", line 7, in hourly_data
    files.get_forecast(lat, long)
  File "/Users/avinasharavind/Documents/Weather_Projects/NWS_Forecast_Page/python/files.py", line 52, in get_forecast
    response = requests.get(url)
               ^^^^^^^^^^^^^^^^^
  File "/opt/anaconda3/lib/python3.11/site-packages/requests/api.py", line 73, in get
    return request("get", url, params=params, **kwargs)
           ^^^^^^^^^^^^^^^^^^^^^^^^^^^^^^^^^^^^^^^^^^^^
  File "/opt/anaconda3/lib/python3.11/site-packages/requests/api.py", line 59, in request
    return session.request(method=method, url=url, **kwargs)
           ^^^^^^^^^^^^^^^^^^^^^^^^^^^^^^^^^^^^^^^^^^^^^^^^^
  File "/opt/anaconda3/lib/python3.11/site-packages/requests/sessions.py", line 589, in request
    resp = self.send(prep, **send_kwargs)
           ^^^^^^^^^^^^^^^^^^^^^^^^^^^^^^
  File "/opt/anaconda3/lib/python3.11/site-packages/requests/sessions.py", line 703, in send
    r = adapter.send(request, **kwargs)
        ^^^^^^^^^^^^^^^^^^^^^^^^^^^^^^^
  File "/opt/anaconda3/lib/python3.11/site-packages/requests/adapters.py", line 519, in send
    raise ConnectionError(e, request=request)
requests.exceptions.ConnectionError: HTTPSConnectionPool(host='api.weather.gov', port=443): Max retries exceeded with url: /points/42.44,-76.495 (Caused by NameResolutionError("<urllib3.connection.HTTPSConnection object at 0x127cc3410>: Failed to resolve 'api.weather.gov' ([Errno 8] nodename nor servname provided, or not known)"))
